Workbook

Sheet Cómo se usa
A1: El horno de Sara · Gestión de pedidos y finanzas
B3: Qué hace este Excel
B4: Lleva el control de los pedidos que llegan por WhatsApp (estado, cobros, entregas) y de los gastos, y calcula solo ventas, beneficio y pendientes de cobro.
B6: Cómo usarlo, paso a paso
B7: 1. Catálogo: revisa los precios (vienen de la web y son orientativos) y, si quieres ver márgenes, escribe el coste de ingredientes de cada producto.
B8: 2. Pedidos: cuando llegue un encargo, añade una fila nueva debajo de la anterior. Rellena las celdas azules; precio, total y pendiente se calculan solos.
B9: 3. Cuando el cliente pague (señal o total), apunta la cantidad en 'Cobrado'. Cambia el 'Estado' según avance (Confirmado → En preparación → Listo → Entregado).
B10: 4. Gastos: apunta cada compra (ingredientes, cajas, gasolina…) con su categoría e importe.
B11: 5. Resumen: elige el año arriba y verás mes a mes ventas, cobrado, pendiente, gastos y resultado, más ventas por producto y gastos por categoría.
B13: Leyenda de colores
B14: Texto azul = lo escribes tú. Fondo gris = fórmula automática, no la borres. Importe pendiente en rojo = falta por cobrar.
B16: Cómo se cuenta cada cosa (supuestos)
B17: • Cada pedido se asigna al mes de su FECHA DE ENTREGA (columna Año/Mes de Pedidos), no al mes en que se hizo.
... B28: Cuando tengas datos de clientes (nombres, teléfonos), no subas este archivo a un repositorio público.

Sheet Pedidos
A1: Pedidos
A2: Una fila por pedido. Celdas azules = las rellenas tú; celdas grises = se calculan solas (no las toques).
A5: Nº | B5: Fecha del pedido | C5: Cliente | D5: Teléfono | E5: Producto y tamaño | F5: Cantidad | G5: Precio unidad (€) | H5: Total (€) | I5: Entrega | J5: Fecha de entrega | K5: Estado | L5: Forma de pago | M5: Cobrado (€) | N5: Pendiente de cobro (€) | O5: Coste estimado (€) | P5: Margen estimado (€) | Q5: Notas | R5: Año | S5: Mes
A6: =IF(C6="","",ROW()-5) -> 1 | B6: 46307 | C6: EJEMPLO – Marta López (borra esta fila) | D6: 600123456 | E6: Tarta de queso y pistacho – Grande (10–12 raciones) | F6: 2 | G6: =IF(E6="","",IFERROR(INDEX(Catálogo!$D$5:$D$34,MATCH(E6,Catálogo!$C$5:$C$34,0)),"")) -> 34 | H6: =IF(OR(F6="",G6=""),"",F6*G6) -> 68 | I6: Recogida en Alcoy | J6: 46315 | K6: Confirmado | L6: Bizum | M6: 34 | N6: =IF(H6="","",IF(K6="Cancelado",0,H6-M6)) -> 34 | O6: =IF(OR(F6="",E6=""),"",IFERROR(IF(INDEX(Catálogo!$E$5:$E$34,MATCH(E6,Catálogo!$C$5:$C$34,0))=0,"",F6*INDEX(Catálogo!$E$5:$E$34,MATCH(E6,Catálogo!$C$5:$C$34,0))),"")) | P6: =IF(OR(H6="",O6=""),"",H6-O6) | Q6: Sin frutos secos extra. Cumpleaños. | R6: =IF(J6="","",YEAR(J6)) -> 2026 | S6: =IF(J6="","",MONTH(J6)) -> 10
A7: =IF(C7="","",ROW()-5) | G7: =IF(E7="","",IFERROR(INDEX(Catálogo!$D$5:$D$34,MATCH(E7,Catálogo!$C$5:$C$34,0)),"")) | H7: =IF(OR(F7="",G7=""),"",F7*G7) | N7: =IF(H7="","",IF(K7="Cancelado",0,H7-M7)) | O7: =IF(OR(F7="",E7=""),"",IFERROR(IF(INDEX(Catálogo!$E$5:$E$34,MATCH(E7,Catálogo!$C$5:$C$34,0))=0,"",F7*INDEX(Catálogo!$E$5:$E$34,MATCH(E7,Catálogo!$C$5:$C$34,0))),"")) | P7: =IF(OR(H7="",O7=""),"",H7-O7) | R7: =IF(J7="","",YEAR(J7)) | S7: =IF(J7="","",MONTH(J7))
A8: =IF(C8="","",ROW()-5) | G8: =IF(E8="","",IFERROR(INDEX(Catálogo!$D$5:$D$34,MATCH(E8,Catálogo!$C$5:$C$34,0)),"")) | H8: =IF(OR(F8="",G8=""),"",F8*G8) | N8: =IF(H8="","",IF(K8="Cancelado",0,H8-M8)) | O8: =IF(OR(F8="",E8=""),"",IFERROR(IF(INDEX(Catálogo!$E$5:$E$34,MATCH(E8,Catálogo!$C$5:$C$34,0))=0,"",F8*INDEX(Catálogo!$E$5:$E$34,MATCH(E8,Catálogo!$C$5:$C$34,0))),"")) | P8: =IF(OR(H8="",O8=""),"",H8-O8) | R8: =IF(J8="","",YEAR(J8)) | S8: =IF(J8="","",MONTH(J8))
A9: =IF(C9="","",ROW()-5) | G9: =IF(E9="","",IFERROR(INDEX(Catálogo!$D$5:$D$34,MATCH(E9,Catálogo!$C$5:$C$34,0)),"")) | H9: =IF(OR(F9="",G9=""),"",F9*G9) | N9: =IF(H9="","",IF(K9="Cancelado",0,H9-M9)) | O9: =IF(OR(F9="",E9=""),"",IFERROR(IF(INDEX(Catálogo!$E$5:$E$34,MATCH(E9,Catálogo!$C$5:$C$34,0))=0,"",F9*INDEX(Catálogo!$E$5:$E$34,MATCH(E9,Catálogo!$C$5:$C$34,0))),"")) | P9: =IF(OR(H9="",O9=""),"",H9-O9) | R9: =IF(J9="","",YEAR(J9)) | S9: =IF(J9="","",MONTH(J9))
A10: =IF(C10="","",ROW()-5) | G10: =IF(E10="","",IFERROR(INDEX(Catálogo!$D$5:$D$34,MATCH(E10,Catálogo!$C$5:$C$34,0)),"")) | H10: =IF(OR(F10="",G10=""),"",F10*G10) | N10: =IF(H10="","",IF(K10="Cancelado",0,H10-M10)) | O10: =IF(OR(F10="",E10=""),"",IFERROR(IF(INDEX(Catálogo!$E$5:$E$34,MATCH(E10,Catálogo!$C$5:$C$34,0))=0,"",F10*INDEX(Catálogo!$E$5:$E$34,MATCH(E10,Catálogo!$C$5:$C$34,0))),"")) | P10: =IF(OR(H10="",O10=""),"",H10-O10) | R10: =IF(J10="","",YEAR(J10)) | S10: =IF(J10="","",MONTH(J10))
A11: =IF(C11="","",ROW()-5) | G11: =IF(E11="","",IFERROR(INDEX(Catálogo!$D$5:$D$34,MATCH(E11,Catálogo!$C$5:$C$34,0)),"")) | H11: =IF(OR(F11="",G11=""),"",F11*G11) | N11: =IF(H11="","",IF(K11="Cancelado",0,H11-M11)) | O11: =IF(OR(F11="",E11=""),"",IFERROR(IF(INDEX(Catálogo!$E$5:$E$34,MATCH(E11,Catálogo!$C$5:$C$34,0))=0,"",F11*INDEX(Catálogo!$E$5:$E$34,MATCH(E11,Catálogo!$C$5:$C$34,0))),"")) | P11: =IF(OR(H11="",O11=""),"",H11-O11) | R11: =IF(J11="","",YEAR(J11)) | S11: =IF(J11="","",MONTH(J11))
A12: =IF(C12="","",ROW()-5) | G12: =IF(E12="","",IFERROR(INDEX(Catálogo!$D$5:$D$34,MATCH(E12,Catálogo!$C$5:$C$34,0)),"")) | H12: =IF(OR(F12="",G12=""),"",F12*G12) | N12: =IF(H12="","",IF(K12="Cancelado",0,H12-M12)) | O12: =IF(OR(F12="",E12=""),"",IFERROR(IF(INDEX(Catálogo!$E$5:$E$34,MATCH(E12,Catálogo!$C$5:$C$34,0))=0,"",F12*INDEX(Catálogo!$E$5:$E$34,MATCH(E12,Catálogo!$C$5:$C$34,0))),"")) | P12: =IF(OR(H12="",O12=""),"",H12-O12) | R12: =IF(J12="","",YEAR(J12)) | S12: =IF(J12="","",MONTH(J12))
A13: =IF(C13="","",ROW()-5) | G13: =IF(E13="","",IFERROR(INDEX(Catálogo!$D$5:$D$34,MATCH(E13,Catálogo!$C$5:$C$34,0)),"")) | H13: =IF(OR(F13="",G13=""),"",F13*G13) | N13: =IF(H13="","",IF(K13="Cancelado",0,H13-M13)) | O13: =IF(OR(F13="",E13=""),"",IFERROR(IF(INDEX(Catálogo!$E$5:$E$34,MATCH(E13,Catálogo!$C$5:$C$34,0))=0,"",F13*INDEX(Catálogo!$E$5:$E$34,MATCH(E13,Catálogo!$C$5:$C$34,0))),"")) | P13: =IF(OR(H13="",O13=""),"",H13-O13) | R13: =IF(J13="","",YEAR(J13)) | S13: =IF(J13="","",MONTH(J13))
A14: =IF(C14="","",ROW()-5) | G14: =IF(E14="","",IFERROR(INDEX(Catálogo!$D$5:$D$34,MATCH(E14,Catálogo!$C$5:$C$34,0)),"")) | H14: =IF(OR(F14="",G14=""),"",F14*G14) | N14: =IF(H14="","",IF(K14="Cancelado",0,H14-M14)) | O14: =IF(OR(F14="",E14=""),"",IFERROR(IF(INDEX(Catálogo!$E$5:$E$34,MATCH(E14,Catálogo!$C$5:$C$34,0))=0,"",F14*INDEX(Catálogo!$E$5:$E$34,MATCH(E14,Catálogo!$C$5:$C$34,0))),"")) | P14: =IF(OR(H14="",O14=""),"",H14-O14) | R14: =IF(J14="","",YEAR(J14)) | S14: =IF(J14="","",MONTH(J14))
A15: =IF(C15="","",ROW()-5) | G15: =IF(E15="","",IFERROR(INDEX(Catálogo!$D$5:$D$34,MATCH(E15,Catálogo!$C$5:$C$34,0)),"")) | H15: =IF(OR(F15="",G15=""),"",F15*G15) | N15: =IF(H15="","",IF(K15="Cancelado",0,H15-M15)) | O15: =IF(OR(F15="",E15=""),"",IFERROR(IF(INDEX(Catálogo!$E$5:$E$34,MATCH(E15,Catálogo!$C$5:$C$34,0))=0,"",F15*INDEX(Catálogo!$E$5:$E$34,MATCH(E15,Catálogo!$C$5:$C$34,0))),"")) | P15: =IF(OR(H15="",O15=""),"",H15-O15) | R15: =IF(J15="","",YEAR(J15)) | S15: =IF(J15="","",MONTH(J15))
A16: =IF(C16="","",ROW()-5) | G16: =IF(E16="","",IFERROR(INDEX(Catálogo!$D$5:$D$34,MATCH(E16,Catálogo!$C$5:$C$34,0)),"")) | H16: =IF(OR(F16="",G16=""),"",F16*G16) | N16: =IF(H16="","",IF(K16="Cancelado",0,H16-M16)) | O16: =IF(OR(F16="",E16=""),"",IFERROR(IF(INDEX(Catálogo!$E$5:$E$34,MATCH(E16,Catálogo!$C$5:$C$34,0))=0,"",F16*INDEX(Catálogo!$E$5:$E$34,MATCH(E16,Catálogo!$C$5:$C$34,0))),"")) | P16: =IF(OR(H16="",O16=""),"",H16-O16) | R16: =IF(J16="","",YEAR(J16)) | S16: =IF(J16="","",MONTH(J16))
A17: =IF(C17="","",ROW()-5) | G17: =IF(E17="","",IFERROR(INDEX(Catálogo!$D$5:$D$34,MATCH(E17,Catálogo!$C$5:$C$34,0)),"")) | H17: =IF(OR(F17="",G17=""),"",F17*G17) | N17: =IF(H17="","",IF(K17="Cancelado",0,H17-M17)) | O17: =IF(OR(F17="",E17=""),"",IFERROR(IF(INDEX(Catálogo!$E$5:$E$34,MATCH(E17,Catálogo!$C$5:$C$34,0))=0,"",F17*INDEX(Catálogo!$E$5:$E$34,MATCH(E17,Catálogo!$C$5:$C$34,0))),"")) | P17: =IF(OR(H17="",O17=""),"",H17-O17) | R17: =IF(J17="","",YEAR(J17)) | S17: =IF(J17="","",MONTH(J17))
A18: =IF(C18="","",ROW()-5) | G18: =IF(E18="","",IFERROR(INDEX(Catálogo!$D$5:$D$34,MATCH(E18,Catálogo!$C$5:$C$34,0)),"")) | H18: =IF(OR(F18="",G18=""),"",F18*G18) | N18: =IF(H18="","",IF(K18="Cancelado",0,H18-M18)) | O18: =IF(OR(F18="",E18=""),"",IFERROR(IF(INDEX(Catálogo!$E$5:$E$34,MATCH(E18,Catálogo!$C$5:$C$34,0))=0,"",F18*INDEX(Catálogo!$E$5:$E$34,MATCH(E18,Catálogo!$C$5:$C$34,0))),"")) | P18: =IF(OR(H18="",O18=""),"",H18-O18) | R18: =IF(J18="","",YEAR(J18)) | S18: =IF(J18="","",MONTH(J18))
... A305: =IF(C305="","",ROW()-5) | G305: =IF(E305="","",IFERROR(INDEX(Catálogo!$D$5:$D$34,MATCH(E305,Catálogo!$C$5:$C$34,0)),"")) | H305: =IF(OR(F305="",G305=""),"",F305*G305) | N305: =IF(H305="","",IF(K305="Cancelado",0,H305-M305)) | O305: =IF(OR(F305="",E305=""),"",IFERROR(IF(INDEX(Catálogo!$E$5:$E$34,MATCH(E305,Catálogo!$C$5:$C$34,0))=0,"",F305*INDEX(Catálogo!$E$5:$E$34,MATCH(E305,Catálogo!$C$5:$C$34,0))),"")) | P305: =IF(OR(H305="",O305=""),"",H305-O305) | R305: =IF(J305="","",YEAR(J305)) | S305: =IF(J305="","",MONTH(J305))

Sheet Gastos
A1: Gastos
A2: Una fila por compra o gasto real (ticket o factura). Celdas azules = las rellenas tú.
A5: Fecha | B5: Categoría | C5: Concepto | D5: Proveedor / tienda | E5: Importe (€) | F5: Forma de pago | G5: Notas | H5: Año | I5: Mes
A6: 46305 | B6: Ingredientes | C6: EJEMPLO – Queso crema, nata y huevos (borra esta fila) | D6: Mercadona | E6: 42.5 | F6: Efectivo | G6: Para 3 tartas de queso | H6: =IF(A6="","",YEAR(A6)) -> 2026 | I6: =IF(A6="","",MONTH(A6)) -> 10
H7: =IF(A7="","",YEAR(A7)) | I7: =IF(A7="","",MONTH(A7))
H8: =IF(A8="","",YEAR(A8)) | I8: =IF(A8="","",MONTH(A8))
H9: =IF(A9="","",YEAR(A9)) | I9: =IF(A9="","",MONTH(A9))
H10: =IF(A10="","",YEAR(A10)) | I10: =IF(A10="","",MONTH(A10))
H11: =IF(A11="","",YEAR(A11)) | I11: =IF(A11="","",MONTH(A11))
H12: =IF(A12="","",YEAR(A12)) | I12: =IF(A12="","",MONTH(A12))
H13: =IF(A13="","",YEAR(A13)) | I13: =IF(A13="","",MONTH(A13))
H14: =IF(A14="","",YEAR(A14)) | I14: =IF(A14="","",MONTH(A14))
H15: =IF(A15="","",YEAR(A15)) | I15: =IF(A15="","",MONTH(A15))
H16: =IF(A16="","",YEAR(A16)) | I16: =IF(A16="","",MONTH(A16))
H17: =IF(A17="","",YEAR(A17)) | I17: =IF(A17="","",MONTH(A17))
H18: =IF(A18="","",YEAR(A18)) | I18: =IF(A18="","",MONTH(A18))
... H505: =IF(A505="","",YEAR(A505)) | I505: =IF(A505="","",MONTH(A505))

Sheet Resumen
A1: Resumen financiero
A3: Año a mostrar: | B3: 2026 | C3: ← cambia el año y todo se recalcula
A5: Mes | B5: Nº | C5: Pedidos | D5: Ventas (€) | E5: Cobrado (€) | F5: Pendiente de cobro (€) | G5: Gastos (€) | H5: Resultado (ventas − gastos) | I5: Caja (cobrado − gastos) | J5: Margen sobre ventas
A6: Enero | B6: 1 | C6: =COUNTIFS(Pedidos!$R$6:$R$305,$B$3,Pedidos!$S$6:$S$305,$B6,Pedidos!$K$6:$K$305,"<>Cancelado") -> 0 | D6: =SUMIFS(Pedidos!$H$6:$H$305,Pedidos!$R$6:$R$305,$B$3,Pedidos!$S$6:$S$305,$B6,Pedidos!$K$6:$K$305,"<>Cancelado") -> 0 | E6: =SUMIFS(Pedidos!$M$6:$M$305,Pedidos!$R$6:$R$305,$B$3,Pedidos!$S$6:$S$305,$B6,Pedidos!$K$6:$K$305,"<>Cancelado") -> 0 | F6: =SUMIFS(Pedidos!$N$6:$N$305,Pedidos!$R$6:$R$305,$B$3,Pedidos!$S$6:$S$305,$B6,Pedidos!$K$6:$K$305,"<>Cancelado") -> 0 | G6: =SUMIFS(Gastos!$E$6:$E$505,Gastos!$H$6:$H$505,$B$3,Gastos!$I$6:$I$505,$B6) -> 0 | H6: =D6-G6 -> 0 | I6: =E6-G6 -> 0 | J6: =IF(D6=0,0,H6/D6) -> 0
A7: Febrero | B7: 2 | C7: =COUNTIFS(Pedidos!$R$6:$R$305,$B$3,Pedidos!$S$6:$S$305,$B7,Pedidos!$K$6:$K$305,"<>Cancelado") -> 0 | D7: =SUMIFS(Pedidos!$H$6:$H$305,Pedidos!$R$6:$R$305,$B$3,Pedidos!$S$6:$S$305,$B7,Pedidos!$K$6:$K$305,"<>Cancelado") -> 0 | E7: =SUMIFS(Pedidos!$M$6:$M$305,Pedidos!$R$6:$R$305,$B$3,Pedidos!$S$6:$S$305,$B7,Pedidos!$K$6:$K$305,"<>Cancelado") -> 0 | F7: =SUMIFS(Pedidos!$N$6:$N$305,Pedidos!$R$6:$R$305,$B$3,Pedidos!$S$6:$S$305,$B7,Pedidos!$K$6:$K$305,"<>Cancelado") -> 0 | G7: =SUMIFS(Gastos!$E$6:$E$505,Gastos!$H$6:$H$505,$B$3,Gastos!$I$6:$I$505,$B7) -> 0 | H7: =D7-G7 -> 0 | I7: =E7-G7 -> 0 | J7: =IF(D7=0,0,H7/D7) -> 0
A8: Marzo | B8: 3 | C8: =COUNTIFS(Pedidos!$R$6:$R$305,$B$3,Pedidos!$S$6:$S$305,$B8,Pedidos!$K$6:$K$305,"<>Cancelado") -> 0 | D8: =SUMIFS(Pedidos!$H$6:$H$305,Pedidos!$R$6:$R$305,$B$3,Pedidos!$S$6:$S$305,$B8,Pedidos!$K$6:$K$305,"<>Cancelado") -> 0 | E8: =SUMIFS(Pedidos!$M$6:$M$305,Pedidos!$R$6:$R$305,$B$3,Pedidos!$S$6:$S$305,$B8,Pedidos!$K$6:$K$305,"<>Cancelado") -> 0 | F8: =SUMIFS(Pedidos!$N$6:$N$305,Pedidos!$R$6:$R$305,$B$3,Pedidos!$S$6:$S$305,$B8,Pedidos!$K$6:$K$305,"<>Cancelado") -> 0 | G8: =SUMIFS(Gastos!$E$6:$E$505,Gastos!$H$6:$H$505,$B$3,Gastos!$I$6:$I$505,$B8) -> 0 | H8: =D8-G8 -> 0 | I8: =E8-G8 -> 0 | J8: =IF(D8=0,0,H8/D8) -> 0
A9: Abril | B9: 4 | C9: =COUNTIFS(Pedidos!$R$6:$R$305,$B$3,Pedidos!$S$6:$S$305,$B9,Pedidos!$K$6:$K$305,"<>Cancelado") -> 0 | D9: =SUMIFS(Pedidos!$H$6:$H$305,Pedidos!$R$6:$R$305,$B$3,Pedidos!$S$6:$S$305,$B9,Pedidos!$K$6:$K$305,"<>Cancelado") -> 0 | E9: =SUMIFS(Pedidos!$M$6:$M$305,Pedidos!$R$6:$R$305,$B$3,Pedidos!$S$6:$S$305,$B9,Pedidos!$K$6:$K$305,"<>Cancelado") -> 0 | F9: =SUMIFS(Pedidos!$N$6:$N$305,Pedidos!$R$6:$R$305,$B$3,Pedidos!$S$6:$S$305,$B9,Pedidos!$K$6:$K$305,"<>Cancelado") -> 0 | G9: =SUMIFS(Gastos!$E$6:$E$505,Gastos!$H$6:$H$505,$B$3,Gastos!$I$6:$I$505,$B9) -> 0 | H9: =D9-G9 -> 0 | I9: =E9-G9 -> 0 | J9: =IF(D9=0,0,H9/D9) -> 0
A10: Mayo | B10: 5 | C10: =COUNTIFS(Pedidos!$R$6:$R$305,$B$3,Pedidos!$S$6:$S$305,$B10,Pedidos!$K$6:$K$305,"<>Cancelado") -> 0 | D10: =SUMIFS(Pedidos!$H$6:$H$305,Pedidos!$R$6:$R$305,$B$3,Pedidos!$S$6:$S$305,$B10,Pedidos!$K$6:$K$305,"<>Cancelado") -> 0 | E10: =SUMIFS(Pedidos!$M$6:$M$305,Pedidos!$R$6:$R$305,$B$3,Pedidos!$S$6:$S$305,$B10,Pedidos!$K$6:$K$305,"<>Cancelado") -> 0 | F10: =SUMIFS(Pedidos!$N$6:$N$305,Pedidos!$R$6:$R$305,$B$3,Pedidos!$S$6:$S$305,$B10,Pedidos!$K$6:$K$305,"<>Cancelado") -> 0 | G10: =SUMIFS(Gastos!$E$6:$E$505,Gastos!$H$6:$H$505,$B$3,Gastos!$I$6:$I$505,$B10) -> 0 | H10: =D10-G10 -> 0 | I10: =E10-G10 -> 0 | J10: =IF(D10=0,0,H10/D10) -> 0
A11: Junio | B11: 6 | C11: =COUNTIFS(Pedidos!$R$6:$R$305,$B$3,Pedidos!$S$6:$S$305,$B11,Pedidos!$K$6:$K$305,"<>Cancelado") -> 0 | D11: =SUMIFS(Pedidos!$H$6:$H$305,Pedidos!$R$6:$R$305,$B$3,Pedidos!$S$6:$S$305,$B11,Pedidos!$K$6:$K$305,"<>Cancelado") -> 0 | E11: =SUMIFS(Pedidos!$M$6:$M$305,Pedidos!$R$6:$R$305,$B$3,Pedidos!$S$6:$S$305,$B11,Pedidos!$K$6:$K$305,"<>Cancelado") -> 0 | F11: =SUMIFS(Pedidos!$N$6:$N$305,Pedidos!$R$6:$R$305,$B$3,Pedidos!$S$6:$S$305,$B11,Pedidos!$K$6:$K$305,"<>Cancelado") -> 0 | G11: =SUMIFS(Gastos!$E$6:$E$505,Gastos!$H$6:$H$505,$B$3,Gastos!$I$6:$I$505,$B11) -> 0 | H11: =D11-G11 -> 0 | I11: =E11-G11 -> 0 | J11: =IF(D11=0,0,H11/D11) -> 0
A12: Julio | B12: 7 | C12: =COUNTIFS(Pedidos!$R$6:$R$305,$B$3,Pedidos!$S$6:$S$305,$B12,Pedidos!$K$6:$K$305,"<>Cancelado") -> 0 | D12: =SUMIFS(Pedidos!$H$6:$H$305,Pedidos!$R$6:$R$305,$B$3,Pedidos!$S$6:$S$305,$B12,Pedidos!$K$6:$K$305,"<>Cancelado") -> 0 | E12: =SUMIFS(Pedidos!$M$6:$M$305,Pedidos!$R$6:$R$305,$B$3,Pedidos!$S$6:$S$305,$B12,Pedidos!$K$6:$K$305,"<>Cancelado") -> 0 | F12: =SUMIFS(Pedidos!$N$6:$N$305,Pedidos!$R$6:$R$305,$B$3,Pedidos!$S$6:$S$305,$B12,Pedidos!$K$6:$K$305,"<>Cancelado") -> 0 | G12: =SUMIFS(Gastos!$E$6:$E$505,Gastos!$H$6:$H$505,$B$3,Gastos!$I$6:$I$505,$B12) -> 0 | H12: =D12-G12 -> 0 | I12: =E12-G12 -> 0 | J12: =IF(D12=0,0,H12/D12) -> 0
A13: Agosto | B13: 8 | C13: =COUNTIFS(Pedidos!$R$6:$R$305,$B$3,Pedidos!$S$6:$S$305,$B13,Pedidos!$K$6:$K$305,"<>Cancelado") -> 0 | D13: =SUMIFS(Pedidos!$H$6:$H$305,Pedidos!$R$6:$R$305,$B$3,Pedidos!$S$6:$S$305,$B13,Pedidos!$K$6:$K$305,"<>Cancelado") -> 0 | E13: =SUMIFS(Pedidos!$M$6:$M$305,Pedidos!$R$6:$R$305,$B$3,Pedidos!$S$6:$S$305,$B13,Pedidos!$K$6:$K$305,"<>Cancelado") -> 0 | F13: =SUMIFS(Pedidos!$N$6:$N$305,Pedidos!$R$6:$R$305,$B$3,Pedidos!$S$6:$S$305,$B13,Pedidos!$K$6:$K$305,"<>Cancelado") -> 0 | G13: =SUMIFS(Gastos!$E$6:$E$505,Gastos!$H$6:$H$505,$B$3,Gastos!$I$6:$I$505,$B13) -> 0 | H13: =D13-G13 -> 0 | I13: =E13-G13 -> 0 | J13: =IF(D13=0,0,H13/D13) -> 0
A14: Septiembre | B14: 9 | C14: =COUNTIFS(Pedidos!$R$6:$R$305,$B$3,Pedidos!$S$6:$S$305,$B14,Pedidos!$K$6:$K$305,"<>Cancelado") -> 0 | D14: =SUMIFS(Pedidos!$H$6:$H$305,Pedidos!$R$6:$R$305,$B$3,Pedidos!$S$6:$S$305,$B14,Pedidos!$K$6:$K$305,"<>Cancelado") -> 0 | E14: =SUMIFS(Pedidos!$M$6:$M$305,Pedidos!$R$6:$R$305,$B$3,Pedidos!$S$6:$S$305,$B14,Pedidos!$K$6:$K$305,"<>Cancelado") -> 0 | F14: =SUMIFS(Pedidos!$N$6:$N$305,Pedidos!$R$6:$R$305,$B$3,Pedidos!$S$6:$S$305,$B14,Pedidos!$K$6:$K$305,"<>Cancelado") -> 0 | G14: =SUMIFS(Gastos!$E$6:$E$505,Gastos!$H$6:$H$505,$B$3,Gastos!$I$6:$I$505,$B14) -> 0 | H14: =D14-G14 -> 0 | I14: =E14-G14 -> 0 | J14: =IF(D14=0,0,H14/D14) -> 0
A15: Octubre | B15: 10 | C15: =COUNTIFS(Pedidos!$R$6:$R$305,$B$3,Pedidos!$S$6:$S$305,$B15,Pedidos!$K$6:$K$305,"<>Cancelado") -> 1 | D15: =SUMIFS(Pedidos!$H$6:$H$305,Pedidos!$R$6:$R$305,$B$3,Pedidos!$S$6:$S$305,$B15,Pedidos!$K$6:$K$305,"<>Cancelado") -> 68 | E15: =SUMIFS(Pedidos!$M$6:$M$305,Pedidos!$R$6:$R$305,$B$3,Pedidos!$S$6:$S$305,$B15,Pedidos!$K$6:$K$305,"<>Cancelado") -> 34 | F15: =SUMIFS(Pedidos!$N$6:$N$305,Pedidos!$R$6:$R$305,$B$3,Pedidos!$S$6:$S$305,$B15,Pedidos!$K$6:$K$305,"<>Cancelado") -> 34 | G15: =SUMIFS(Gastos!$E$6:$E$505,Gastos!$H$6:$H$505,$B$3,Gastos!$I$6:$I$505,$B15) -> 42.5 | H15: =D15-G15 -> 25.5 | I15: =E15-G15 -> -8.5 | J15: =IF(D15=0,0,H15/D15) -> 0.375
A16: Noviembre | B16: 11 | C16: =COUNTIFS(Pedidos!$R$6:$R$305,$B$3,Pedidos!$S$6:$S$305,$B16,Pedidos!$K$6:$K$305,"<>Cancelado") -> 0 | D16: =SUMIFS(Pedidos!$H$6:$H$305,Pedidos!$R$6:$R$305,$B$3,Pedidos!$S$6:$S$305,$B16,Pedidos!$K$6:$K$305,"<>Cancelado") -> 0 | E16: =SUMIFS(Pedidos!$M$6:$M$305,Pedidos!$R$6:$R$305,$B$3,Pedidos!$S$6:$S$305,$B16,Pedidos!$K$6:$K$305,"<>Cancelado") -> 0 | F16: =SUMIFS(Pedidos!$N$6:$N$305,Pedidos!$R$6:$R$305,$B$3,Pedidos!$S$6:$S$305,$B16,Pedidos!$K$6:$K$305,"<>Cancelado") -> 0 | G16: =SUMIFS(Gastos!$E$6:$E$505,Gastos!$H$6:$H$505,$B$3,Gastos!$I$6:$I$505,$B16) -> 0 | H16: =D16-G16 -> 0 | I16: =E16-G16 -> 0 | J16: =IF(D16=0,0,H16/D16) -> 0
A17: Diciembre | B17: 12 | C17: =COUNTIFS(Pedidos!$R$6:$R$305,$B$3,Pedidos!$S$6:$S$305,$B17,Pedidos!$K$6:$K$305,"<>Cancelado") -> 0 | D17: =SUMIFS(Pedidos!$H$6:$H$305,Pedidos!$R$6:$R$305,$B$3,Pedidos!$S$6:$S$305,$B17,Pedidos!$K$6:$K$305,"<>Cancelado") -> 0 | E17: =SUMIFS(Pedidos!$M$6:$M$305,Pedidos!$R$6:$R$305,$B$3,Pedidos!$S$6:$S$305,$B17,Pedidos!$K$6:$K$305,"<>Cancelado") -> 0 | F17: =SUMIFS(Pedidos!$N$6:$N$305,Pedidos!$R$6:$R$305,$B$3,Pedidos!$S$6:$S$305,$B17,Pedidos!$K$6:$K$305,"<>Cancelado") -> 0 | G17: =SUMIFS(Gastos!$E$6:$E$505,Gastos!$H$6:$H$505,$B$3,Gastos!$I$6:$I$505,$B17) -> 0 | H17: =D17-G17 -> 0 | I17: =E17-G17 -> 0 | J17: =IF(D17=0,0,H17/D17) -> 0
A18: TOTAL AÑO | C18: =SUM(C6:C17) -> 1 | D18: =SUM(D6:D17) -> 68 | E18: =SUM(E6:E17) -> 34 | F18: =SUM(F6:F17) -> 34 | G18: =SUM(G6:G17) -> 42.5 | H18: =SUM(H6:H17) -> 25.5 | I18: =SUM(I6:I17) -> -8.5 | J18: =IF(D18=0,0,H18/D18) -> 0.375
A20: Indicadores
A21: Ticket medio por pedido (€) | D21: =IF(C18=0,0,D18/C18) -> 68
A22: Pendiente de cobro, todos los años (€) | D22: =SUM(Pedidos!$N$6:$N$305) -> 34
A23: Pedidos sin entregar (confirmados, en preparación o listos) | D23: =COUNTIF(Pedidos!$K$6:$K$305,"Confirmado")+COUNTIF(Pedidos!$K$6:$K$305,"En preparación")+COUNTIF(Pedidos!$K$6:$K$305,"Listo") -> 1
A24: Pedidos por confirmar | D24: =COUNTIF(Pedidos!$K$6:$K$305,"Pendiente de confirmar") -> 0
A25: Pedidos cancelados (año) | D25: =COUNTIFS(Pedidos!$R$6:$R$305,$B$3,Pedidos!$K$6:$K$305,"Cancelado") -> 0
A26: Coste estimado de ingredientes según catálogo (€) | D26: =SUMIFS(Pedidos!$O$6:$O$305,Pedidos!$R$6:$R$305,$B$3,Pedidos!$K$6:$K$305,"<>Cancelado") -> 0
A27: Gastos en ingredientes realmente comprados (€) | D27: =SUMIFS(Gastos!$E$6:$E$505,Gastos!$H$6:$H$505,$B$3,Gastos!$B$6:$B$505,"Ingredientes") -> 42.5
A29: Ventas por producto (año seleccionado)
A30: Producto y tamaño | D30: Unidades | E30: Ventas (€) | F30: % de las ventas
A31: =IF(Catálogo!C5="","",Catálogo!C5) -> Tarta de queso y pistacho – Pequeña (6–8 raciones) | D31: =IF($A31="","",SUMIFS(Pedidos!$F$6:$F$305,Pedidos!$E$6:$E$305,$A31,Pedidos!$R$6:$R$305,$B$3,Pedidos!$K$6:$K$305,"<>Cancelado")) -> 0 | E31: =IF($A31="","",SUMIFS(Pedidos!$H$6:$H$305,Pedidos!$E$6:$E$305,$A31,Pedidos!$R$6:$R$305,$B$3,Pedidos!$K$6:$K$305,"<>Cancelado")) -> 0 | F31: =IF(OR($A31="",$D$18=0),"",E31/$D$18) -> 0
A32: =IF(Catálogo!C6="","",Catálogo!C6) -> Tarta de queso y pistacho – Grande (10–12 raciones) | D32: =IF($A32="","",SUMIFS(Pedidos!$F$6:$F$305,Pedidos!$E$6:$E$305,$A32,Pedidos!$R$6:$R$305,$B$3,Pedidos!$K$6:$K$305,"<>Cancelado")) -> 2 | E32: =IF($A32="","",SUMIFS(Pedidos!$H$6:$H$305,Pedidos!$E$6:$E$305,$A32,Pedidos!$R$6:$R$305,$B$3,Pedidos!$K$6:$K$305,"<>Cancelado")) -> 68 | F32: =IF(OR($A32="",$D$18=0),"",E32/$D$18) -> 1
A33: =IF(Catálogo!C7="","",Catálogo!C7) -> Tarta de queso al horno – Pequeña (6–8 raciones) | D33: =IF($A33="","",SUMIFS(Pedidos!$F$6:$F$305,Pedidos!$E$6:$E$305,$A33,Pedidos!$R$6:$R$305,$B$3,Pedidos!$K$6:$K$305,"<>Cancelado")) -> 0 | E33: =IF($A33="","",SUMIFS(Pedidos!$H$6:$H$305,Pedidos!$E$6:$E$305,$A33,Pedidos!$R$6:$R$305,$B$3,Pedidos!$K$6:$K$305,"<>Cancelado")) -> 0 | F33: =IF(OR($A33="",$D$18=0),"",E33/$D$18) -> 0
A34: =IF(Catálogo!C8="","",Catálogo!C8) -> Tarta de queso al horno – Grande (10–12 raciones) | D34: =IF($A34="","",SUMIFS(Pedidos!$F$6:$F$305,Pedidos!$E$6:$E$305,$A34,Pedidos!$R$6:$R$305,$B$3,Pedidos!$K$6:$K$305,"<>Cancelado")) -> 0 | E34: =IF($A34="","",SUMIFS(Pedidos!$H$6:$H$305,Pedidos!$E$6:$E$305,$A34,Pedidos!$R$6:$R$305,$B$3,Pedidos!$K$6:$K$305,"<>Cancelado")) -> 0 | F34: =IF(OR($A34="",$D$18=0),"",E34/$D$18) -> 0
A35: =IF(Catálogo!C9="","",Catálogo!C9) -> Tarta de chocolate – Pequeña (6–8 raciones) | D35: =IF($A35="","",SUMIFS(Pedidos!$F$6:$F$305,Pedidos!$E$6:$E$305,$A35,Pedidos!$R$6:$R$305,$B$3,Pedidos!$K$6:$K$305,"<>Cancelado")) -> 0 | E35: =IF($A35="","",SUMIFS(Pedidos!$H$6:$H$305,Pedidos!$E$6:$E$305,$A35,Pedidos!$R$6:$R$305,$B$3,Pedidos!$K$6:$K$305,"<>Cancelado")) -> 0 | F35: =IF(OR($A35="",$D$18=0),"",E35/$D$18) -> 0
A36: =IF(Catálogo!C10="","",Catálogo!C10) -> Tarta de chocolate – Grande (10–12 raciones) | D36: =IF($A36="","",SUMIFS(Pedidos!$F$6:$F$305,Pedidos!$E$6:$E$305,$A36,Pedidos!$R$6:$R$305,$B$3,Pedidos!$K$6:$K$305,"<>Cancelado")) -> 0 | E36: =IF($A36="","",SUMIFS(Pedidos!$H$6:$H$305,Pedidos!$E$6:$E$305,$A36,Pedidos!$R$6:$R$305,$B$3,Pedidos!$K$6:$K$305,"<>Cancelado")) -> 0 | F36: =IF(OR($A36="",$D$18=0),"",E36/$D$18) -> 0
A37: =IF(Catálogo!C11="","",Catálogo!C11) -> Corona de chocolate – Entera (10–12 raciones) | D37: =IF($A37="","",SUMIFS(Pedidos!$F$6:$F$305,Pedidos!$E$6:$E$305,$A37,Pedidos!$R$6:$R$305,$B$3,Pedidos!$K$6:$K$305,"<>Cancelado")) -> 0 | E37: =IF($A37="","",SUMIFS(Pedidos!$H$6:$H$305,Pedidos!$E$6:$E$305,$A37,Pedidos!$R$6:$R$305,$B$3,Pedidos!$K$6:$K$305,"<>Cancelado")) -> 0 | F37: =IF(OR($A37="",$D$18=0),"",E37/$D$18) -> 0
A38: =IF(Catálogo!C12="","",Catálogo!C12) -> Banoffee – Entera (8 raciones) | D38: =IF($A38="","",SUMIFS(Pedidos!$F$6:$F$305,Pedidos!$E$6:$E$305,$A38,Pedidos!$R$6:$R$305,$B$3,Pedidos!$K$6:$K$305,"<>Cancelado")) -> 0 | E38: =IF($A38="","",SUMIFS(Pedidos!$H$6:$H$305,Pedidos!$E$6:$E$305,$A38,Pedidos!$R$6:$R$305,$B$3,Pedidos!$K$6:$K$305,"<>Cancelado")) -> 0 | F38: =IF(OR($A38="",$D$18=0),"",E38/$D$18) -> 0
A39: =IF(Catálogo!C13="","",Catálogo!C13) -> Banoffee – Porción individual | D39: =IF($A39="","",SUMIFS(Pedidos!$F$6:$F$305,Pedidos!$E$6:$E$305,$A39,Pedidos!$R$6:$R$305,$B$3,Pedidos!$K$6:$K$305,"<>Cancelado")) -> 0 | E39: =IF($A39="","",SUMIFS(Pedidos!$H$6:$H$305,Pedidos!$E$6:$E$305,$A39,Pedidos!$R$6:$R$305,$B$3,Pedidos!$K$6:$K$305,"<>Cancelado")) -> 0 | F39: =IF(OR($A39="",$D$18=0),"",E39/$D$18) -> 0
A40: =IF(Catálogo!C14="","",Catálogo!C14) -> Tarta holandesa – Entera (8 raciones) | D40: =IF($A40="","",SUMIFS(Pedidos!$F$6:$F$305,Pedidos!$E$6:$E$305,$A40,Pedidos!$R$6:$R$305,$B$3,Pedidos!$K$6:$K$305,"<>Cancelado")) -> 0 | E40: =IF($A40="","",SUMIFS(Pedidos!$H$6:$H$305,Pedidos!$E$6:$E$305,$A40,Pedidos!$R$6:$R$305,$B$3,Pedidos!$K$6:$K$305,"<>Cancelado")) -> 0 | F40: =IF(OR($A40="",$D$18=0),"",E40/$D$18) -> 0
A41: =IF(Catálogo!C15="","",Catálogo!C15) -> Tarta holandesa – Porción individual | D41: =IF($A41="","",SUMIFS(Pedidos!$F$6:$F$305,Pedidos!$E$6:$E$305,$A41,Pedidos!$R$6:$R$305,$B$3,Pedidos!$K$6:$K$305,"<>Cancelado")) -> 0 | E41: =IF($A41="","",SUMIFS(Pedidos!$H$6:$H$305,Pedidos!$E$6:$E$305,$A41,Pedidos!$R$6:$R$305,$B$3,Pedidos!$K$6:$K$305,"<>Cancelado")) -> 0 | F41: =IF(OR($A41="",$D$18=0),"",E41/$D$18) -> 0
A42: =IF(Catálogo!C16="","",Catálogo!C16) -> Cookies con trozos – Caja de 4 | D42: =IF($A42="","",SUMIFS(Pedidos!$F$6:$F$305,Pedidos!$E$6:$E$305,$A42,Pedidos!$R$6:$R$305,$B$3,Pedidos!$K$6:$K$305,"<>Cancelado")) -> 0 | E42: =IF($A42="","",SUMIFS(Pedidos!$H$6:$H$305,Pedidos!$E$6:$E$305,$A42,Pedidos!$R$6:$R$305,$B$3,Pedidos!$K$6:$K$305,"<>Cancelado")) -> 0 | F42: =IF(OR($A42="",$D$18=0),"",E42/$D$18) -> 0
... A50: =IF(Catálogo!C24="","",Catálogo!C24) | D50: =IF($A50="","",SUMIFS(Pedidos!$F$6:$F$305,Pedidos!$E$6:$E$305,$A50,Pedidos!$R$6:$R$305,$B$3,Pedidos!$K$6:$K$305,"<>Cancelado")) | E50: =IF($A50="","",SUMIFS(Pedidos!$H$6:$H$305,Pedidos!$E$6:$E$305,$A50,Pedidos!$R$6:$R$305,$B$3,Pedidos!$K$6:$K$305,"<>Cancelado")) | F50: =IF(OR($A50="",$D$18=0),"",E50/$D$18)
A52: Gastos por categoría (año seleccionado)
...

Sheet Catálogo
A1: Catálogo de productos y precios
A2: Precios copiados de la web (js/main.js, son orientativos). Rellena el coste de ingredientes por unidad para ver el margen.
A4: Producto | B4: Tamaño / formato | C4: Clave (se usa en Pedidos) | D4: Precio de venta (€) | E4: Coste ingredientes por unidad (€) | F4: Margen (€) | G4: Margen (%) | I4: Añade productos nuevos en las filas vacías de abajo (hasta la fila 34).
A5: Tarta de queso y pistacho | B5: Pequeña (6–8 raciones) | C5: =IF(A5="","",A5&" – "&B5) -> Tarta de queso y pistacho – Pequeña (6–8 raciones) | D5: 24 | F5: =IF(OR(D5="",E5=""),"",D5-E5) | G5: =IF(OR(D5="",E5="",D5=0),"",F5/D5)
A6: Tarta de queso y pistacho | B6: Grande (10–12 raciones) | C6: =IF(A6="","",A6&" – "&B6) -> Tarta de queso y pistacho – Grande (10–12 raciones) | D6: 34 | F6: =IF(OR(D6="",E6=""),"",D6-E6) | G6: =IF(OR(D6="",E6="",D6=0),"",F6/D6)
A7: Tarta de queso al horno | B7: Pequeña (6–8 raciones) | C7: =IF(A7="","",A7&" – "&B7) -> Tarta de queso al horno – Pequeña (6–8 raciones) | D7: 20 | F7: =IF(OR(D7="",E7=""),"",D7-E7) | G7: =IF(OR(D7="",E7="",D7=0),"",F7/D7)
A8: Tarta de queso al horno | B8: Grande (10–12 raciones) | C8: =IF(A8="","",A8&" – "&B8) -> Tarta de queso al horno – Grande (10–12 raciones) | D8: 30 | F8: =IF(OR(D8="",E8=""),"",D8-E8) | G8: =IF(OR(D8="",E8="",D8=0),"",F8/D8)
A9: Tarta de chocolate | B9: Pequeña (6–8 raciones) | C9: =IF(A9="","",A9&" – "&B9) -> Tarta de chocolate – Pequeña (6–8 raciones) | D9: 22 | F9: =IF(OR(D9="",E9=""),"",D9-E9) | G9: =IF(OR(D9="",E9="",D9=0),"",F9/D9)
A10: Tarta de chocolate | B10: Grande (10–12 raciones) | C10: =IF(A10="","",A10&" – "&B10) -> Tarta de chocolate – Grande (10–12 raciones) | D10: 32 | F10: =IF(OR(D10="",E10=""),"",D10-E10) | G10: =IF(OR(D10="",E10="",D10=0),"",F10/D10)
A11: Corona de chocolate | B11: Entera (10–12 raciones) | C11: =IF(A11="","",A11&" – "&B11) -> Corona de chocolate – Entera (10–12 raciones) | D11: 22 | F11: =IF(OR(D11="",E11=""),"",D11-E11) | G11: =IF(OR(D11="",E11="",D11=0),"",F11/D11)
A12: Banoffee | B12: Entera (8 raciones) | C12: =IF(A12="","",A12&" – "&B12) -> Banoffee – Entera (8 raciones) | D12: 26 | F12: =IF(OR(D12="",E12=""),"",D12-E12) | G12: =IF(OR(D12="",E12="",D12=0),"",F12/D12)
A13: Banoffee | B13: Porción individual | C13: =IF(A13="","",A13&" – "&B13) -> Banoffee – Porción individual | D13: 4 | F13: =IF(OR(D13="",E13=""),"",D13-E13) | G13: =IF(OR(D13="",E13="",D13=0),"",F13/D13)
A14: Tarta holandesa | B14: Entera (8 raciones) | C14: =IF(A14="","",A14&" – "&B14) -> Tarta holandesa – Entera (8 raciones) | D14: 26 | F14: =IF(OR(D14="",E14=""),"",D14-E14) | G14: =IF(OR(D14="",E14="",D14=0),"",F14/D14)
A15: Tarta holandesa | B15: Porción individual | C15: =IF(A15="","",A15&" – "&B15) -> Tarta holandesa – Porción individual | D15: 4 | F15: =IF(OR(D15="",E15=""),"",D15-E15) | G15: =IF(OR(D15="",E15="",D15=0),"",F15/D15)
A16: Cookies con trozos | B16: Caja de 4 | C16: =IF(A16="","",A16&" – "&B16) -> Cookies con trozos – Caja de 4 | D16: 10 | F16: =IF(OR(D16="",E16=""),"",D16-E16) | G16: =IF(OR(D16="",E16="",D16=0),"",F16/D16)
A17: Cookies con trozos | B17: Caja de 6 | C17: =IF(A17="","",A17&" – "&B17) -> Cookies con trozos – Caja de 6 | D17: 14 | F17: =IF(OR(D17="",E17=""),"",D17-E17) | G17: =IF(OR(D17="",E17="",D17=0),"",F17/D17)
C18: =IF(A18="","",A18&" – "&B18) | F18: =IF(OR(D18="",E18=""),"",D18-E18) | G18: =IF(OR(D18="",E18="",D18=0),"",F18/D18)
C19: =IF(A19="","",A19&" – "&B19) | F19: =IF(OR(D19="",E19=""),"",D19-E19) | G19: =IF(OR(D19="",E19="",D19=0),"",F19/D19)
C20: =IF(A20="","",A20&" – "&B20) | F20: =IF(OR(D20="",E20=""),"",D20-E20) | G20: =IF(OR(D20="",E20="",D20=0),"",F20/D20)
C21: =IF(A21="","",A21&" – "&B21) | F21: =IF(OR(D21="",E21=""),"",D21-E21) | G21: =IF(OR(D21="",E21="",D21=0),"",F21/D21)
C22: =IF(A22="","",A22&" – "&B22) | F22: =IF(OR(D22="",E22=""),"",D22-E22) | G22: =IF(OR(D22="",E22="",D22=0),"",F22/D22)
C23: =IF(A23="","",A23&" – "&B23) | F23: =IF(OR(D23="",E23=""),"",D23-E23) | G23: =IF(OR(D23="",E23="",D23=0),"",F23/D23)
C24: =IF(A24="","",A24&" – "&B24) | F24: =IF(OR(D24="",E24=""),"",D24-E24) | G24: =IF(OR(D24="",E24="",D24=0),"",F24/D24)
C25: =IF(A25="","",A25&" – "&B25) | F25: =IF(OR(D25="",E25=""),"",D25-E25) | G25: =IF(OR(D25="",E25="",D25=0),"",F25/D25)
C26: =IF(A26="","",A26&" – "&B26) | F26: =IF(OR(D26="",E26=""),"",D26-E26) | G26: =IF(OR(D26="",E26="",D26=0),"",F26/D26)
C27: =IF(A27="","",A27&" – "&B27) | F27: =IF(OR(D27="",E27=""),"",D27-E27) | G27: =IF(OR(D27="",E27="",D27=0),"",F27/D27)
C28: =IF(A28="","",A28&" – "&B28) | F28: =IF(OR(D28="",E28=""),"",D28-E28) | G28: =IF(OR(D28="",E28="",D28=0),"",F28/D28)
C29: =IF(A29="","",A29&" – "&B29) | F29: =IF(OR(D29="",E29=""),"",D29-E29) | G29: =IF(OR(D29="",E29="",D29=0),"",F29/D29)
... C34: =IF(A34="","",A34&" – "&B34) | F34: =IF(OR(D34="",E34=""),"",D34-E34) | G34: =IF(OR(D34="",E34="",D34=0),"",F34/D34)

Sheet Listas
A1: Listas desplegables
A2: Puedes añadir o cambiar opciones; las listas de las otras hojas las leen de aquí.
A4: Estado del pedido | B4: Forma de pago | C4: Entrega | D4: Categoría de gasto
A5: Pendiente de confirmar | B5: Efectivo | C5: Recogida en Alcoy | D5: Ingredientes
A6: Confirmado | B6: Bizum | C6: Entrega a domicilio en Alcoy | D6: Envases y embalaje
A7: En preparación | B7: Transferencia | D7: Material y utensilios
A8: Listo | D8: Marketing y fotos
A9: Entregado | D9: Transporte y gasolina
A10: Cancelado | D10: Comisiones y cuotas
D11: Impuestos y autónomos
D12: Otros
